# Debugging Report: LaTeX Image Rendering Failure

## 1. Project Goal

The objective is to create a Telegram quiz bot that can dynamically render questions containing mathematical LaTeX code into images. These images are then sent to the user, followed by a poll for the answer.

The intended architecture is:
1.  A Python bot using the `python-telegram-bot` library.
2.  A `rendering_service` that uses `matplotlib` and a local LaTeX installation (MiKTeX) to convert LaTeX strings into PNG images.
3.  An AWS S3 bucket used as a cache. If an image for a specific question has been rendered before, it should be fetched from the S3 cache. If not, it should be rendered, uploaded to the cache, and then sent.

## 2. The Problem

When a user requests a quiz question that requires LaTeX rendering, the bot fails. The user receives a fallback message saying "(Error rendering question)" instead of an image. The application logs show a series of errors that have evolved as we've attempted to fix them.

## 3. Diagnostic Journey & Failed Attempts

Here is a chronological summary of the errors encountered and the steps taken to resolve them. This documents a persistent and complex issue involving environment configuration, AWS permissions, and LaTeX syntax.

### Initial State: `ValueError` and `NameError`

*   **Symptom:** The bot would not start, crashing immediately.
*   **Error Log:** `ValueError: No DATABASE_URL set` and `NameError: name 'create_engine' is not defined`.
*   **Analysis:** These were identified as application setup issues. The first was due to the `.env` file not being loaded correctly when running `python -m src.main`. The second was caused by a faulty refactoring that removed necessary `sqlalchemy` imports.
*   **Attempted Fixes:**
    1.  Made the `.env` file loading path in `src/main.py` absolute.
    2.  Restored the missing imports to `src/database.py`.

**Result:** These initial fixes were successful, allowing the bot to start and connect to the database, which led us to the core rendering problem.

---

### Second State: S3 `AccessDenied` Error

*   **Symptom:** The bot ran, but when a question was requested, the rendering failed. The user received the fallback error message.
*   **Error Log:** `botocore.exceptions.ClientError: An error occurred (AccessDenied) when calling the PutObject operation`.
*   **Analysis:** The diagnostic script `diagnose_s3.py` confirmed that the application could authenticate with AWS, but the IAM user `adaptive-bot-s3-worker` did not have permission to upload files (`s3:PutObject`).
*   **Attempted Fix:** The IAM policy for the user was updated to allow the `s3:PutObject` action on the `rendered-cache/*` resource.

**Result:** This fix was partially successful. It resolved the `PutObject` error and led to the next error in the chain.

---

### Third State: S3 `403 Forbidden` on `HeadObject`

*   **Symptom:** Same as the previous state.
*   **Error Log:** `botocore.exceptions.ClientError: An error occurred (403) when calling the HeadObject operation: Forbidden`.
*   **Analysis:** The bot could now upload files but couldn't check if a file already existed in the cache. This is because the `HeadObject` action requires `s3:GetObject` or `s3:ListBucket` permissions, which were missing.
*   **Attempted Fix:** The IAM policy was updated again to include `s3:GetObject` on the objects and `s3:ListBucket` on the bucket itself.

**Result:** This fix was also successful and resolved all S3 permission issues, leading to the final and most persistent error.

---

### Fourth State: `Wrong type of the web page content`

*   **Symptom:** Same as the previous state.
*   **Error Log:** `telegram.error.BadRequest: Wrong type of the web page content`.
*   **Analysis:** This error indicated that the entire AWS S3 pipeline was now working correctly (authentication, upload, public access). However, the file being uploaded was corrupted or empty. The problem was isolated to the image generation step in `rendering_service.py`.
*   **Attempted Fixes (Multiple):** Several attempts were made to fix the `matplotlib` and LaTeX code generation, assuming the issue was with Python f-strings, backslash escaping, or incorrect LaTeX syntax (`$` wrapping a `minipage` environment).

**Result:** All attempts to fix the LaTeX string generation failed, leading to the current error.

## 4. Current Situation & The Core Unresolved Issue

After a series of fixes, we have successfully resolved all environment, configuration, and AWS permission issues. The current error is now purely with the LaTeX rendering engine.

*   **Current Error Log:**

    ```
    RuntimeError: latex was not able to process the following string:
b'lp'

Here is the full command invocation and its output:
...
! Undefined control sequence.
<recently read> \n
l.14 \usepackage{amsmath}
 \usepackage{amsfonts}
\usepackage{amssymb}
\use...
    ```

*   **Analysis of the Error:**
    1.  The Python script is correctly calling the `latex.exe` command on the system.
    2.  The LaTeX engine (MiKTeX) starts but fails with an `! Undefined control sequence` error.
    3.  The error is triggered by a newline character `\n` being present inside the LaTeX preamble string that `matplotlib` is configured with.

*   **Root Cause:** The `text.latex.preamble` setting in `rendering_service.py` is configured with a multi-line Python string. These newlines are passed literally to the LaTeX engine, which interprets them as an invalid command, causing the rendering to fail.

## 5. Relevant Code for Review

Here is the current state of the rendering service that is causing the error. A developer should focus here.

**File: `src/services/rendering_service.py`**

```python
import os
import hashlib
import boto3
from botocore.exceptions import NoCredentialsError, ClientError
import logging
import matplotlib
matplotlib.use('Agg')
import matplotlib.pyplot as plt
from io import BytesIO

from src.config import S3_BUCKET_NAME, AWS_REGION

logger = logging.getLogger(__name__)

# PROBLEM AREA: The multi-line string here contains '\n' characters,
# which are passed to the LaTeX engine, causing an error.
plt.rcParams.update({
    "text.usetex": True,
    "font.family": "serif",
    "font.serif": ["Computer Modern Roman"],
    "text.latex.preamble": r"""
        \usepackage{amsmath}
        \usepackage{amsfonts}
        \usepackage{amssymb}
        \usepackage{circuitikz}
    """,
})

s3_client = boto3.client('s3', region_name=AWS_REGION)

def _render_single_latex_string(latex_string: str) -> str | None:
    # This function contains the matplotlib rendering logic that fails.
    # ... (implementation as of last attempt)
    pass

def render_full_question_to_image_urls(question_text: str, options: list[str]) -> dict[str, str | list[str]] | None:
    # This function calls the rendering logic.
    # ... (implementation as of last attempt)
    pass
```

## 6. Help Needed

We are seeking a definitive solution to the `! Undefined control sequence` error being produced by the LaTeX engine when called from `matplotlib`. The core issue is how to correctly pass the list of required `\usepackage` commands to `matplotlib`'s `text.latex.preamble` setting without introducing characters that are illegal in the LaTeX preamble context.
